Workbook
Name ANGULAR_DEFLECTION: LAMBDA(thickness, length, flexivity, temp_change, (67*flexivity*temp_change*length)/thickness)

Sheet Flexivity
A1: Material Type | B1: -100 | C1: -50 | D1: 0 | E1: 50 | F1: 100 | G1: 150 | H1: 200 | I1: 250 | J1: 300 | K1: 350 | L1: 400 | M1: 450 | N1: 500 | O1: 550 | P1: 600 | Q1: 650 | R1: 700 | S1: 800 | T1: 900 | U1: 1000 | V1: Modulus
A2: A1 | B2: 146 | C2: 148 | D2: 149 | E2: 150 | F2: 150 | G2: 150 | H2: 149 | I2: 146 | J2: 142 | K2: 134 | V2: 18
A3: B1 | B3: 126 | C3: 135 | D3: 144 | E3: 150 | F3: 150 | G3: 150 | H3: 150 | I3: 146 | J3: 139 | K3: 130 | L3: 116 | M3: 92 | N3: 68 | O3: 47 | P3: 38 | Q3: 35 | R3: 31 | S3: 28 | T3: 24 | U3: 22 | V3: 25
A4: B2 | B4: 108 | C4: 114 | D4: 118 | E4: 123 | F4: 126 | G4: 129 | H4: 130 | I4: 132 | J4: 134 | K4: 135 | L4: 137 | M4: 138 | N4: 135 | O4: 124 | P4: 92 | Q4: 69 | R4: 55 | S4: 47 | T4: 44 | U4: 38 | V4: 25
A5: B3 | B5: 87 | C5: 96 | D5: 105 | E5: 112 | F5: 119 | G5: 121 | H5: 125 | I5: 127 | J5: 131 | K5: 132 | L5: 133 | M5: 133 | N5: 135 | O5: 135 | P5: 129 | Q5: 107 | R5: 80 | S5: 51 | T5: 47 | U5: 40 | V5: 25
A6: B11 | B6: 113 | C6: 120 | D6: 125 | E6: 135 | F6: 137 | G6: 142 | H6: 146 | I6: 146 | J6: 146 | K6: 146 | L6: 146 | M6: 142 | N6: 120 | O6: 98 | P6: 83 | Q6: 65 | R6: 57 | S6: 37 | T6: 33 | U6: 30 | V6: 25
A7: BN | B7: 35 | C7: 38 | D7: 44 | E7: 44 | F7: 45 | G7: 47 | H7: 48 | I7: 47 | J7: 47 | K7: 43 | L7: 38 | M7: 36 | N7: 33 | O7: 30 | P7: 29 | Q7: 23 | R7: 15 | V7: 28.5
A8: BP1 | B8: 150 | C8: 168 | D8: 189 | E8: 185 | F8: 185 | G8: 185 | H8: 186 | I8: 186 | J8: 186 | K8: 185 | L8: 183 | M8: 165 | N8: 139 | O8: 129 | P8: 126 | V8: 20
A9: B100R | B9: 102 | C9: 110 | D9: 112 | E9: 113 | F9: 113 | G9: 114 | H9: 114 | I9: 113 | J9: 106 | K9: 100 | L9: 86 | M9: 65 | N9: 42 | O9: 32 | P9: 25 | Q9: 22 | R9: 17 | S9: 16 | T9: 16 | U9: 16 | V9: 26
A10: B125R | B10: 113 | C10: 123 | D10: 128 | E10: 129 | F10: 130 | G10: 129 | H10: 128 | I10: 126 | J10: 125 | K10: 119 | L10: 99 | M10: 77 | N10: 56 | O10: 46 | P10: 32 | Q10: 28 | R10: 25 | S10: 23 | T10: 19 | U10: 17 | V10: 26
A11: B150R | B11: 118 | C11: 126 | D11: 135 | E11: 136 | F11: 137 | G11: 138 | H11: 136 | I11: 135 | J11: 130 | K11: 121 | L11: 105 | M11: 76 | N11: 53 | O11: 42 | P11: 37 | Q11: 31 | R11: 26 | S11: 19 | T11: 17 | U11: 16 | V11: 26
A12: B175R | B12: 122 | C12: 129 | D12: 141 | E12: 142 | F12: 142 | G12: 143 | H12: 142 | I12: 141 | J12: 135 | K12: 125 | L12: 109 | M12: 78 | N12: 54 | O12: 45 | P12: 38 | Q12: 31 | R12: 28 | S12: 21 | T12: 18 | U12: 16 | V12: 25.5
A13: B200R | B13: 124 | C13: 134 | D13: 143 | E13: 143 | F13: 144 | G13: 145 | H13: 145 | I13: 140 | J13: 134 | K13: 126 | L13: 112 | M13: 81 | N13: 50 | O13: 40 | P13: 31 | Q13: 30 | R13: 26 | S13: 25 | T13: 22 | U13: 18 | V13: 25.5
A14: B250R | B14: 130 | C14: 140 | D14: 142 | E14: 147 | F14: 147 | G14: 147 | H14: 147 | I14: 144 | J14: 139 | K14: 125 | L14: 112 | M14: 82 | N14: 67 | O14: 53 | P14: 44 | Q14: 38 | R14: 30 | S14: 28 | T14: 25 | U14: 22 | V14: 25.5
A15: B300R | B15: 132 | C15: 142 | D15: 145 | E15: 149 | F15: 149 | G15: 150 | H15: 149 | I15: 146 | J15: 141 | K15: 128 | L15: 112 | M15: 83 | N15: 67 | O15: 53 | P15: 44 | Q15: 38 | R15: 30 | S15: 28 | T15: 25 | U15: 22 | V15: 25
A16: B350R | B16: 135 | C16: 140 | D16: 147 | E16: 149 | F16: 150 | G16: 150 | H16: 148 | I16: 144 | J16: 140 | K16: 129 | L16: 111 | M16: 81 | N16: 64 | O16: 48 | P16: 33 | Q16: 31 | R16: 29 | S16: 25 | T16: 23 | U16: 21 | V16: 25
A17: B400R | B17: 135 | C17: 140 | D17: 147 | E17: 149 | F17: 150 | G17: 150 | H17: 148 | I17: 144 | J17: 140 | K17: 129 | L17: 111 | M17: 81 | N17: 64 | O17: 48 | P17: 33 | Q17: 31 | R17: 29 | S17: 25 | T17: 23 | U17: 21 | V17: 25
A18: C1 | B18: 136 | C18: 142 | D18: 149 | E18: 153 | F18: 154 | G18: 154 | H18: 153 | I18: 149 | J18: 144 | K18: 117 | L18: 102 | M18: 85 | N18: 65 | O18: 49 | P18: 39 | Q18: 31 | R18: 25 | S18: 15 | T18: 14 | U18: 12 | V18: 25
A19: C3 | B19: 99 | C19: 107 | D19: 113 | E19: 119 | F19: 121 | G19: 124 | H19: 126 | I19: 129 | J19: 132 | K19: 137 | L19: 138 | M19: 140 | N19: 146 | O19: 148 | P19: 148 | Q19: 131 | R19: 116 | S19: 62 | T19: 26 | U19: 15 | V19: 25
A20: C11 | B20: 118 | C20: 129 | D20: 136 | E20: 140 | F20: 143 | G20: 145 | H20: 149 | I20: 151 | J20: 152 | K20: 152 | L20: 152 | M20: 149 | N20: 125 | O20: 95 | P20: 73 | Q20: 57 | R20: 45 | S20: 31 | T20: 19 | U20: 15 | V20: 25
... A25: E5 | B25: 44 | C25: 47 | D25: 51 | E25: 55 | F25: 57 | G25: 60 | H25: 66 | I25: 68 | J25: 71 | K25: 74 | L25: 75 | M25: 77 | N25: 81 | O25: 82 | P25: 83 | Q25: 83 | R25: 83 | S25: 82 | T25: 59 | U25: 45 | V25: 25.5
A26: F15R | B26: 63 | C26: 70 | D26: 72 | E26: 73 | F26: 72 | G26: 71 | H26: 67 | I26: 66 | J26: 63 | K26: 52 | L26: 47 | M26: 43 | N26: 38 | O26: 31 | P26: 28 | Q26: 22 | R26: 13 | V26: 20
A27: F20R | B27: 114 | C27: 121 | D27: 124 | E27: 127 | F27: 128 | G27: 129 | H27: 127 | I27: 126 | J27: 118 | K27: 109 | L27: 93 | M27: 68 | N27: 48 | O27: 38 | P27: 28 | Q27: 22 | R27: 15 | V27: 20
A28: F25R | B28: 119 | C28: 130 | D28: 133 | E28: 134 | F28: 135 | G28: 135 | H28: 134 | I28: 129 | J28: 125 | K28: 118 | L28: 97 | M28: 72 | N28: 52 | O28: 41 | P28: 31 | Q28: 25 | R28: 19 | V28: 22
A29: F30R | B29: 129 | C29: 134 | D29: 137 | E29: 139 | F29: 139 | G29: 139 | H29: 137 | I29: 132 | J29: 127 | K29: 118 | L29: 97 | M29: 72 | N29: 52 | O29: 42 | P29: 33 | Q29: 26 | R29: 19 | V29: 23
A30: F35R | B30: 130 | C30: 137 | D30: 141 | E30: 143 | F30: 143 | G30: 141 | H30: 140 | I30: 137 | J30: 130 | K30: 121 | L30: 96 | M30: 72 | N30: 53 | O30: 44 | P30: 36 | Q30: 29 | R30: 21 | V30: 23.5
A31: F40R | B31: 131 | C31: 139 | D31: 142 | E31: 144 | F31: 144 | G31: 144 | H31: 142 | I31: 139 | J31: 135 | K31: 123 | L31: 100 | M31: 72 | N31: 56 | O31: 46 | P31: 39 | Q31: 32 | R31: 23 | V31: 24
A32: F50R | B32: 134 | C32: 141 | D32: 144 | E32: 146 | F32: 146 | G32: 145 | H32: 145 | I32: 142 | J32: 136 | K32: 124 | L32: 101 | M32: 75 | N32: 58 | O32: 47 | P32: 39 | Q32: 32 | R32: 24 | V32: 24
A33: F60R | B33: 133 | C33: 139 | D33: 145 | E33: 146 | F33: 146 | G33: 146 | H33: 144 | I33: 140 | J33: 134 | K33: 123 | L33: 100 | M33: 74 | N33: 58 | O33: 46 | P33: 40 | Q33: 32 | R33: 25 | V33: 24.5
A34: F70R | B34: 135 | C34: 140 | D34: 147 | E34: 147 | F34: 147 | G34: 147 | H34: 144 | I34: 141 | J34: 135 | K34: 123 | L34: 100 | M34: 75 | N34: 59 | O34: 46 | P34: 32 | Q34: 32 | R34: 25 | V34: 24.5
A35: F90R | B35: 137 | C35: 143 | D35: 145 | E35: 147 | F35: 149 | G35: 149 | H35: 146 | I35: 143 | J35: 137 | K35: 128 | L35: 107 | M35: 75 | N35: 60 | O35: 47 | P35: 41 | Q35: 34 | R35: 27 | V35: 25
A36: F100R | B36: 137 | C36: 143 | D36: 145 | E36: 148 | F36: 149 | G36: 149 | H36: 147 | I36: 143 | J36: 138 | K36: 128 | L36: 110 | M36: 77 | N36: 65 | O36: 49 | P36: 41 | Q36: 34 | R36: 29 | V36: 25
A37: F125R | B37: 135 | C37: 143 | D37: 145 | E37: 148 | F37: 149 | G37: 149 | H37: 147 | I37: 143 | J37: 138 | K37: 128 | L37: 110 | M37: 77 | N37: 65 | O37: 49 | P37: 41 | Q37: 34 | R37: 29 | V37: 25
A38: G1 | B38: 124 | C38: 130 | D38: 137 | E38: 138 | F38: 139 | G38: 139 | H38: 138 | I38: 135 | J38: 132 | K38: 120 | L38: 99 | M38: 75 | N38: 60 | O38: 37 | P38: 30 | Q38: 30 | R38: 24 | S38: 15 | T38: 9 | U38: 5 | V38: 25
A39: G3 | B39: 83 | C39: 89 | D39: 95 | E39: 97 | F39: 101 | G39: 107 | H39: 110 | I39: 116 | J39: 119 | K39: 121 | L39: 121 | M39: 121 | N39: 121 | O39: 121 | P39: 115 | Q39: 95 | R39: 68 | S39: 52 | T39: 39 | U39: 32 | V39: 25
A40: G7 | B40: 60 | C40: 61 | D40: 61 | E40: 61 | F40: 61 | G40: 61 | H40: 61 | I40: 61 | J40: 61 | K40: 61 | L40: 61 | M40: 61 | N40: 61 | O40: 61 | P40: 61 | Q40: 61 | R40: 61 | S40: 61 | T40: 45 | U40: 39 | V40: 27.5
A41: GB14 | B41: 95 | C41: 99 | D41: 102 | E41: 103 | F41: 104 | G41: 103 | H41: 102 | I41: 101 | J41: 100 | K41: 86 | L41: 64 | M41: 57 | N41: 45 | O41: 37 | P41: 27 | Q41: 24 | R41: 22 | S41: 18 | T41: 15 | U41: 13 | V41: 26
A42: J1 | B42: 124 | C42: 129 | D42: 132 | E42: 134 | F42: 135 | G42: 135 | H42: 134 | I42: 131 | J42: 130 | K42: 115 | L42: 89 | M42: 63 | N42: 48 | O42: 39 | P42: 29 | V42: 19
A43: J7 | B43: 54 | C43: 56 | D43: 56 | E43: 56 | F43: 56 | G43: 56 | H43: 56 | I43: 56 | J43: 56 | K43: 56 | L43: 56 | M43: 56 | N43: 56 | O43: 56 | P43: 56 | V43: 22
A44: M7 | B44: 38 | C44: 40 | D44: 40 | E44: 40 | F44: 40 | G44: 40 | H44: 40 | I44: 39 | J44: 39 | K44: 39 | L44: 39 | M44: 39 | N44: 39 | O44: 39 | P44: 39 | Q44: 39 | R44: 39 | S44: 37 | T44: 35 | U44: 32 | V44: 27.5
...

Sheet SpecificDeflection
A1: Material | B1: -50 | C1: 0 | D1: 50 | E1: 100 | F1: 150 | G1: 200 | H1: 250 | I1: 300 | J1: 350 | K1: 400 | L1: 450 | M1: 500
A2: A1 | B2: 1.41 | C2: 1.43 | D2: 1.43 | E2: 1.41 | F2: 1.35
A3: B1 | B3: 1.2 | C3: 1.37 | D3: 1.43 | E3: 1.43 | F3: 1.33 | G3: 1.11 | H3: 0.65 | I3: 0.36 | J3: 0.3 | K3: 0.27 | L3: 0.25 | M3: 0.22
A4: B2 | B4: 1.03 | C4: 1.13 | D4: 1.2 | E4: 1.24 | F4: 1.29 | G4: 1.31 | H4: 1.29 | I4: 0.88 | J4: 0.52 | K4: 0.45 | L4: 0.42 | M4: 0.36
A5: B3 | B5: 0.91 | C5: 1.02 | D5: 1.14 | E5: 1.18 | F5: 1.24 | G5: 1.26 | H5: 1.27 | I5: 1.25 | J5: 0.96 | K5: 0.62 | L5: 0.47 | M5: 0.43
A6: B11 | B6: 1.14 | C6: 1.25 | D6: 1.32 | E6: 1.39 | F6: 1.39 | G6: 1.39 | H6: 1.22 | I6: 0.87 | J6: 0.6 | K6: 0.45 | L6: 0.33 | M6: 0.31
A7: BN | B7: 0.36 | C7: 0.42 | D7: 0.44 | E7: 0.46 | F7: 0.45 | G7: 0.37 | H7: 0.32 | I7: 0.29 | J7: 0.2
A8: BP1 | B8: 1.43 | C8: 1.71 | D8: 1.76 | E8: 1.77 | F8: 1.77 | G8: 1.74 | H8: 1.32 | I8: 1.2
A9: B100R | B9: 0.97 | C9: 1.07 | D9: 1.08 | E9: 1.09 | F9: 1.01 | G9: 0.82 | H9: 0.4 | I9: 0.24 | J9: 0.16 | K9: 0.15 | L9: 0.15 | M9: 0.15
A10: B125R | B10: 1.09 | C10: 1.22 | D10: 1.24 | E10: 1.22 | F10: 1.19 | G10: 0.94 | H10: 0.53 | I10: 0.31 | J10: 0.24 | K10: 0.22 | L10: 0.18 | M10: 0.16
A11: B150R | B11: 1.13 | C11: 1.29 | D11: 1.31 | E11: 1.3 | F11: 1.24 | G11: 1 | H11: 0.51 | I11: 0.35 | J11: 0.25 | K11: 0.18 | L11: 0.16 | M11: 0.15
A12: B175R | B12: 1.16 | C12: 1.35 | D12: 1.35 | E12: 1.35 | F12: 1.29 | G12: 1.04 | H12: 0.52 | I12: 0.36 | J12: 0.27 | K12: 0.2 | L12: 0.17 | M12: 0.15
A13: B200R | B13: 1.18 | C13: 1.36 | D13: 1.37 | E13: 1.38 | F13: 1.29 | G13: 1.07 | H13: 0.48 | I13: 0.3 | J13: 0.25 | K13: 0.24 | L13: 0.21 | M13: 0.17
A14: B250R | B14: 1.24 | C14: 1.35 | D14: 1.4 | E14: 1.4 | F14: 1.33 | G14: 1.07 | H14: 0.64 | I14: 0.42 | J14: 0.33 | K14: 0.28 | L14: 0.26 | M14: 0.23
A15: B300R | B15: 1.26 | C15: 1.38 | D15: 1.42 | E15: 1.42 | F15: 1.35 | G15: 1.07 | H15: 0.64 | I15: 0.42 | J15: 0.33 | K15: 0.28 | L15: 0.26 | M15: 0.23
A16: B350R | B16: 1.29 | C16: 1.4 | D16: 1.43 | E16: 1.41 | F16: 1.34 | G16: 1.06 | H16: 0.61 | I16: 0.31 | J16: 0.29 | K16: 0.26 | L16: 0.23 | M16: 0.21
A17: B400R | B17: 1.29 | C17: 1.4 | D17: 1.43 | E17: 1.41 | F17: 1.34 | G17: 1.06 | H17: 0.61 | I17: 1.31 | J17: 0.29 | K17: 0.26 | L17: 0.23 | M17: 0.21
A18: C1 | B18: 1.3 | C18: 1.42 | D18: 1.47 | E18: 1.46 | F18: 1.37 | G18: 0.97 | H18: 0.62 | I18: 0.37 | J18: 0.24 | K18: 0.18 | L18: 0.14 | M18: 0.12
A19: C3 | B19: 0.95 | C19: 1.08 | D19: 1.16 | E19: 1.2 | F19: 1.26 | G19: 1.32 | H19: 1.39 | I19: 1.41 | J19: 1.11 | K19: 0.58 | L19: 0.25 | M19: 0.21
A20: C11 | B20: 1.13 | C20: 1.3 | D20: 1.36 | E20: 1.42 | F20: 1.45 | G20: 1.45 | H20: 1.19 | I20: 0.7 | J20: 0.43 | K20: 0.3 | L20: 0.18 | M20: 0.16
... A25: E5 | B25: 0.45 | C25: 0.52 | D25: 0.55 | E25: 0.63 | F25: 0.68 | G25: 0.72 | H25: 0.77 | I25: 0.78 | J25: 0.79 | K25: 0.78 | L25: 0.69 | M25: 0.52
A26: F15R | B26: 0.6 | C26: 0.69 | D26: 0.69 | E26: 0.64 | F26: 0.6 | G26: 0.45 | H26: 0.36 | I26: 0.27 | J26: 0.12
A27: F20R | B27: 1.09 | C27: 1.18 | D27: 1.22 | E27: 1.21 | F27: 1.13 | G27: 0.89 | H27: 0.46 | I27: 0.32 | J27: 0.19
A28: F25R | B28: 1.14 | C28: 1.26 | D28: 1.29 | E28: 1.28 | F28: 1.19 | G28: 0.93 | H28: 0.5 | I28: 0.3 | J28: 0.18
A29: F30R | B29: 1.23 | C29: 1.31 | D29: 1.33 | E29: 1.31 | F29: 1.21 | G29: 0.93 | H29: 0.5 | I29: 0.31 | J29: 0.18
A30: F35R | B30: 1.24 | C30: 1.35 | D30: 1.36 | E30: 1.34 | F30: 1.24 | G30: 0.92 | H30: 0.51 | I30: 0.34 | J30: 0.2
A31: F40R | B31: 1.25 | C31: 1.35 | D31: 1.37 | E31: 1.35 | F31: 1.29 | G31: 0.95 | H31: 0.53 | I31: 0.37 | J31: 0.22
A32: F50R | B32: 1.28 | C32: 1.37 | D32: 1.39 | E32: 1.38 | F32: 1.3 | G32: 0.96 | H32: 0.55 | I32: 0.37 | J32: 0.23
A33: F60R | B33: 1.27 | C33: 1.38 | D33: 1.39 | E33: 1.37 | F33: 1.28 | G33: 0.95 | H33: 0.55 | I33: 0.38 | J33: 0.24
A34: F70R | B34: 1.29 | C34: 1.4 | D34: 1.4 | E34: 1.37 | F34: 1.29 | G34: 0.95 | H34: 0.56 | I34: 0.38 | J34: 0.24
A35: F90R | B35: 1.31 | C35: 1.38 | D35: 1.42 | E35: 1.39 | F35: 1.31 | G35: 1.02 | H35: 0.57 | I35: 0.38 | J35: 0.26
A36: F100R | B36: 1.31 | C36: 1.38 | D36: 1.42 | E36: 1.4 | F36: 1.32 | G36: 1.05 | H36: 0.62 | I36: 0.39 | J36: 0.28
A37: F125R | B37: 1.31 | C37: 1.76 | D37: 1.81 | E37: 1.82 | F37: 1.82 | G37: 1.79 | H37: 1.36 | I37: 1.23
A38: G1 | B38: 1.26 | C38: 1.32 | D38: 1.33 | E38: 1.31 | F38: 1.26 | G38: 0.97 | H38: 0.62 | I38: 0.41 | J38: 0.27 | K38: 0.18 | L38: 0.11 | M38: 0.08
A39: G3 | B39: 0.79 | C39: 0.91 | D39: 0.96 | E39: 1.05 | F39: 1.14 | G39: 1.15 | H39: 1.15 | I39: 1.1 | J39: 0.65 | K39: 0.5 | L39: 0.44 | M39: 0.35
A40: G7 | B40: 0.58 | C40: 0.58 | D40: 0.58 | E40: 0.58 | F40: 0.58 | G40: 0.58 | H40: 0.58 | I40: 0.58 | J40: 0.58 | K40: 0.58 | L40: 0.52 | M40: 0.41
A41: GB14 | B41: 0.91 | C41: 0.97 | D41: 0.99 | E41: 0.97 | F41: 0.95 | G41: 0.61 | H41: 0.43 | I41: 0.26 | J41: 0.21 | K41: 0.17 | L41: 0.14 | M41: 0.12
A42: J1 | B42: 1.18 | C42: 1.26 | D42: 1.29 | E42: 1.28 | F42: 1.24 | G42: 0.85 | H42: 0.46 | I42: 0.28
A43: J7 | B43: 0.53 | C43: 0.53 | D43: 0.53 | E43: 0.53 | F43: 0.53 | G43: 0.53 | H43: 0.53 | I43: 0.53 | J43: 0.37 | K43: 0.36 | L43: 0.34 | M43: 0.32
A44: M7 | B44: 0.38 | C44: 0.38 | D44: 0.38 | E44: 0.38 | F44: 0.37 | G44: 0.37 | H44: 0.37 | I44: 0.37 | J44: 0.37 | K44: 0.31 | L44: 0.26 | M44: 0.2
...

Sheet Calculator (Imperial)
A1: Inputs
A2: T1 (°F) | B2: 0
A3: T2 (°F) | B3: 250
A4: Material | B4: P675R
A5: Thickness t (inches) | B5: 0.006
A6: Thickness t (mm) | B6: =CONVERT(B5,"in","mm") -> 0.1524
A7: Width w (inches) | B7: 0.09375
A8: Width w (mm) | B8: =CONVERT(B7,"in","mm") -> 2.38125
A9: Required Deflection A (per PDF units) | B9: 0.001
A10: Required Angular Rotation (deg) | B10: 300
A12: T1 (°C) | B12: =ROUND((B2-32)*5/9,6) -> -17.777778
A13: T2 (°C) | B13: =ROUND((B3-32)*5/9,6) -> 121.11111
A14: ΔT (°C) | B14: =B13-B12 -> 138.88889
E15: =MATCH($B$4, Flexivity!$A:$A, 0) -> 68
A16: Flexivity @ T1 | B16: =IFERROR($K$16 + (($B$2-$G$16)/($I$16-$G$16))*($M$16-$K$16), "") -> 208 | D16: Flex row | E16: =MATCH($B$2, Flexivity!$1:$1, 1) -> 4 | F16: x1 T1 | G16: {=INDEX(Flexivity!$1:$1,1,$E$16)} -> 0 | H16: x2 T1 | I16: {=INDEX(Flexivity!$1:$1,1,$E$16+1)} -> 50 | J16: y1 T1 | K16: {=INDEX(Flexivity!$A:$ZZ,$E$15,$E$16)} -> 208 | L16: y2 T1 | M16: {=INDEX(Flexivity!$A:$ZZ,$E$15,$E$16+1)} -> 215
A17: Flexivity @ T2 | B17: =IFERROR($K$17 + (($B$3-$G$17)/($I$17-$G$17))*($M$17-$K$17), "") -> 216 | D17: Flex col T1 | F17: x1 T2 | G17: {=INDEX(Flexivity!$1:$1,1,$E$18)} -> 250 | H17: x2 T2 | I17: {=INDEX(Flexivity!$1:$1,1,$E$18+1)} -> 300 | J17: y1 T2 | K17: {=INDEX(Flexivity!$A:$ZZ,$E$15,$E$18)} -> 216 | L17: y2 T2 | M17: {=INDEX(Flexivity!$A:$ZZ,$E$15,$E$18+1)} -> 216
A18: Avg Flexivity (F) | B18: =IFERROR(AVERAGE(B16,B17), "") -> 212 | D18: Flex col T2 | E18: =MATCH($B$3, Flexivity!$1:$1, 1) -> 9
B19: 211.16
A22: Modulus of Elasticity | B22: {=XLOOKUP($B$4, Flexivity!$A:$A, Flexivity!$V:$V)} -> 20
A23: Spec. Deflection @ T1 | B23: =IFERROR($K$23 + (($B$12-$G$23)/($I$23-$G$23))*($M$23-$K$23), "") -> 1.8662222 | D23: Defl row | E23: =MATCH($B$4, SpecificDeflection!$A:$A, 0) -> 68 | F23: x1 T1 | G23: {=INDEX(SpecificDeflection!$1:$1,1,$E$24)} -> -50 | H23: x2 T1 | I23: {=INDEX(SpecificDeflection!$1:$1,1,$E$24+1)} -> 0 | J23: y1 T1 | K23: {=INDEX(SpecificDeflection!$A:$ZZ,$E$23,$E$24)} -> 1.66 | L23: y2 T1 | M23: {=INDEX(SpecificDeflection!$A:$ZZ,$E$23,$E$24+1)} -> 1.98
A24: Spec. Deflection @ T2 | B24: =IFERROR($K$24 + (($B$13-$G$24)/($I$24-$G$24))*($M$24-$K$24), "") -> 2.06 | D24: Defl col T1 | E24: =MATCH($B$12, SpecificDeflection!$1:$1, 1) -> 2 | F24: x1 T2 | G24: {=INDEX(SpecificDeflection!$1:$1,1,$E$25)} -> 100 | H24: x2 T2 | I24: {=INDEX(SpecificDeflection!$1:$1,1,$E$25+1)} -> 150 | J24: y1 T2 | K24: {=INDEX(SpecificDeflection!$A:$ZZ,$E$23,$E$25)} -> 2.06 | L24: y2 T2 | M24: {=INDEX(SpecificDeflection!$A:$ZZ,$E$23,$E$25+1)} -> 2.06
A25: Avg Spec. Deflection (A) | B25: =IFERROR(AVERAGE(B23,B24), "") -> 1.9631111 | D25: Defl col T2 | E25: =MATCH($B$13, SpecificDeflection!$1:$1, 1) -> 5
A27: Active Length (inches) | B27: =IFERROR( ( $B$10 * $B$5 ) / ( 67 * ($B$18*10^-7) * ( $B$3 - $B$2 )) , "Check inputs") -> 5.0689946
E28: Angular Rotation | F28: Active Length | G28: Deviation
E29: 300 | F29: =IFERROR( ( $E29 * $B$5 ) / ( 67 * ($B$18*10^-7) * ( $B$3 - $B$2 )) , "Check inputs") -> 5.0689946 | G29: =F29-F29 -> 0
A30: Mechanical Force (Newtons) | B30: =(B22*B10*B8*B6^3)/(690*B27*0.21) -> 0.068852692 | E30: =E29+5 -> 305 | F30: =IFERROR( ( $E30 * $B$5 ) / ( 67 * ($B$18*10^-7) * ( $B$3 - $B$2 )) , "Check inputs") -> 5.1534779 | G30: =F30-$F29 -> 0.084483244
E31: =E30+5 -> 310 | F31: =IFERROR( ( $E31 * $B$5 ) / ( 67 * ($B$18*10^-7) * ( $B$3 - $B$2 )) , "Check inputs") -> 5.2379611 | G31: =F31-$F30 -> 0.084483244
A32: Test Cases for Deflection | E32: =E31+5 -> 315 | F32: =IFERROR( ( $E32 * $B$5 ) / ( 67 * ($B$18*10^-7) * ( $B$3 - $B$2 )) , "Check inputs") -> 5.3224444 | G32: =F32-$F31 -> 0.084483244
A33: Material | B33: Thickness | C33: Length (in) | E33: =E32+5 -> 320 | F33: =IFERROR( ( $E33 * $B$5 ) / ( 67 * ($B$18*10^-7) * ( $B$3 - $B$2 )) , "Check inputs") -> 5.4069276 | G33: =F33-$F32 -> 0.084483244 | I33: 0.168966 every 10 degrees
A34: P675R | B34: 0.006 | C34: 0.5692 | E34: =E33+5 -> 325 | F34: =IFERROR( ( $E34 * $B$5 ) / ( 67 * ($B$18*10^-7) * ( $B$3 - $B$2 )) , "Check inputs") -> 5.4914109 | G34: =F34-$F33 -> 0.084483244
A35: B3 | B35: 0.006 | C35: 1.0653 | E35: =E34+5 -> 330 | F35: =IFERROR( ( $E35 * $B$5 ) / ( 67 * ($B$18*10^-7) * ( $B$3 - $B$2 )) , "Check inputs") -> 5.5758941 | G35: =F35-$F34 -> 0.084483244
A38: Material | B38: Nominal Flexivity | C38: Upper Flexivity | D38: Lower Flexivity | E38: Nominal Angle Span | F38: Upper Angle Span | G38: Lower Angle Span | H38: Nominal Temperature Span | I38: Upper Temperature Span | J38: Lower Temperature Span
A39: B3/TM30 | B39: =118*10^-7 -> 1.18e-05 | C39: =B39+(B39*5%) -> 1.239e-05 | D39: =B39-(B39*5%) -> 1.121e-05 | E39: =ANGULAR_DEFLECTION(Physical_Dims[Thickness (in)],Physical_Dims[Active Length (in)],B39,500) -> 271.06286 | F39: =ANGULAR_DEFLECTION(Physical_Dims[Thickness (in)],Physical_Dims[Active Length (in)],C39,500) -> 284.616 | G39: =ANGULAR_DEFLECTION(Physical_Dims[Thickness (in)],Physical_Dims[Active Length (in)],D39,500) -> 257.50971 | H39: 600
A40: E4/TM4 | B40: =86*10^-7 -> 8.6e-06 | C40: =B40+(B40*5%) -> 9.03e-06 | D40: =B40-(B40*5%) -> 8.17e-06
A41: E5/TM5 | B41: =64*10^-7 -> 6.4e-06 | C41: =B41+(B41*5%) -> 6.72e-06 | D41: =B41-(B41*5%) -> 6.08e-06
A42: P675R/TM2 | B42: =217*10^-7 -> 2.17e-05 | C42: =B42+(B42*5%) -> 2.2785e-05 | D42: =B42-(B42*5%) -> 2.0615e-05

Sheet Sheet2
A1: Thickness (in) | B1: Active Length (in)
A2: 0.00875 | B2: 6

Sheet Calculator (Metric)
A1: Inputs
A2: T1 (°F) | B2: -40
A3: T2 (°F) | B3: 180
A4: Material | B4: P675R
A5: Thickness t (inches) | B5: 0.006
A6: Thickness t (mm) | B6: =CONVERT(B5,"in","mm") -> 0.1524
A7: Width w (inches) | B7: 0.062
A8: Width w (mm) | B8: =CONVERT(B7,"in","mm") -> 1.5748
A9: Required Deflection A (per PDF units) | B9: 0.001
A10: Required Angular Rotation (deg) | B10: 300
A12: T1 (°C) | B12: =ROUND((B2-32)*5/9,6) -> -40
A13: T2 (°C) | B13: =ROUND((B3-32)*5/9,6) -> 82.222222
A14: ΔT (°C) | B14: =B13-B12 -> 122.22222
E15: =MATCH($B$4, Flexivity!$A:$A, 0) -> 68
A16: Flexivity @ T1 | B16: =IFERROR($K$16 + (($B$2-$G$16)/($I$16-$G$16))*($M$16-$K$16), "") -> 198.4 | D16: Flex row | E16: =MATCH($B$2, Flexivity!$1:$1, 1) -> 3 | F16: x1 T1 | G16: {=INDEX(Flexivity!$1:$1,1,$E$16)} -> -50 | H16: x2 T1 | I16: {=INDEX(Flexivity!$1:$1,1,$E$16+1)} -> 0 | J16: y1 T1 | K16: {=INDEX(Flexivity!$A:$ZZ,$E$15,$E$16)} -> 196 | L16: y2 T1 | M16: {=INDEX(Flexivity!$A:$ZZ,$E$15,$E$16+1)} -> 208
A17: Flexivity @ T2 | B17: =IFERROR($K$17 + (($B$3-$G$17)/($I$17-$G$17))*($M$17-$K$17), "") -> 215.6 | D17: Flex col T1 | F17: x1 T2 | G17: {=INDEX(Flexivity!$1:$1,1,$E$18)} -> 150 | H17: x2 T2 | I17: {=INDEX(Flexivity!$1:$1,1,$E$18+1)} -> 200 | J17: y1 T2 | K17: {=INDEX(Flexivity!$A:$ZZ,$E$15,$E$18)} -> 215 | L17: y2 T2 | M17: {=INDEX(Flexivity!$A:$ZZ,$E$15,$E$18+1)} -> 216
A18: Avg Flexivity (F) | B18: =IFERROR(AVERAGE(B16,B17), "") -> 207 | D18: Flex col T2 | E18: =MATCH($B$3, Flexivity!$1:$1, 1) -> 7
B19: 211.16
A22: Modulus of Elasticity | B22: {=XLOOKUP($B$4, Flexivity!$A:$A, Flexivity!$V:$V)} -> 20
A23: Spec. Deflection @ T1 | B23: =IFERROR($K$23 + (($B$12-$G$23)/($I$23-$G$23))*($M$23-$K$23), "") -> 1.724 | D23: Defl row | E23: =MATCH($B$4, SpecificDeflection!$A:$A, 0) -> 68 | F23: x1 T1 | G23: {=INDEX(SpecificDeflection!$1:$1,1,$E$24)} -> -50 | H23: x2 T1 | I23: {=INDEX(SpecificDeflection!$1:$1,1,$E$24+1)} -> 0 | J23: y1 T1 | K23: {=INDEX(SpecificDeflection!$A:$ZZ,$E$23,$E$24)} -> 1.66 | L23: y2 T1 | M23: {=INDEX(SpecificDeflection!$A:$ZZ,$E$23,$E$24+1)} -> 1.98
A24: Spec. Deflection @ T2 | B24: =IFERROR($K$24 + (($B$13-$G$24)/($I$24-$G$24))*($M$24-$K$24), "") -> 2.06 | D24: Defl col T1 | E24: =MATCH($B$12, SpecificDeflection!$1:$1, 1) -> 2 | F24: x1 T2 | G24: {=INDEX(SpecificDeflection!$1:$1,1,$E$25)} -> 50 | H24: x2 T2 | I24: {=INDEX(SpecificDeflection!$1:$1,1,$E$25+1)} -> 100 | J24: y1 T2 | K24: {=INDEX(SpecificDeflection!$A:$ZZ,$E$23,$E$25)} -> 2.06 | L24: y2 T2 | M24: {=INDEX(SpecificDeflection!$A:$ZZ,$E$23,$E$25+1)} -> 2.06
A25: Avg Spec. Deflection (A) | B25: =IFERROR(AVERAGE(B23,B24), "") -> 1.892 | D25: Defl col T2 | E25: =MATCH($B$13, SpecificDeflection!$1:$1, 1) -> 4
A27: Active Length (mm) | B27: =IFERROR( ( $B$10 * 8 * $B$6 ) / ( ($B$25*10^-5) * ( $B$13 - $B$12 ) * 1000) , "Check inputs") -> 158.17029 | D27: Required Thickness (mm) | E27: =IFERROR( ( $B$10 * 8 * $B$6 ) / ( $B$18 * ( $B$13 - $B$12 ) ) * 1000 , "Check inputs") -> 14.456917
A28: Active Length (inches) | B28: =CONVERT(B27,"mm","in") -> 6.2271766 | D28: Required Thickness (in)
A30: Mechanical Force (Newtons) | B30: =(B22*B10*B8*B6^3)/(690*B27*0.21) -> 0.0014592788
A32: Test Cases for Deflection
A33: Material | B33: Thickness | C33: Length (in)
A34: P675R | B34: 0.006 | C34: 0.5692
A35: B3 | B35: 0.006 | C35: 1.0653
